<?xml version="1.0" ?>
<!-- =================================================================================== -->
<!-- |    This document was autogenerated by xacro from robot_desc.xacro               | -->
<!-- |    EDITING THIS FILE BY HAND IS NOT RECOMMENDED                                 | -->
<!-- =================================================================================== -->
<robot name="scara_robot">
  <!-- Radius of Joint Cylinder -->
  <!-- ros_control plugin -->
  <gazebo>
    <plugin filename="libgazebo_ros_control.so" name="gazebo_ros_control">
      <robotNamespace>/scara_robot</robotNamespace>
      <robotSimType>gazebo_ros_control/DefaultRobotHWSim</robotSimType>
    </plugin>
  </gazebo>
  <!-- Base -->
  <gazebo reference="base">
    <material>Gazebo/Black</material>
  </gazebo>
  <!-- Joint1_body -->
  <gazebo reference="cyl1">
    <material>Gazebo/Black</material>
  </gazebo>
  <!-- Joint2_body -->
  <gazebo reference="cyl2">
    <material>Gazebo/Black</material>
  </gazebo>
  <!-- Link1 -->
  <gazebo reference="link1">
    <material>Gazebo/Blue</material>
  </gazebo>
  <!-- Link1-horizontal -->
  <gazebo reference="link1_h">
    <material>Gazebo/Blue</material>
  </gazebo>
  <!-- Link2 -->
  <gazebo reference="link2">
    <mu1>0.2</mu1>
    <mu2>0.2</mu2>
    <material>Gazebo/Blue</material>
  </gazebo>
  <!-- Link3 -->
  <gazebo reference="link3">
    <mu1>0.2</mu1>
    <mu2>0.2</mu2>
    <material>Gazebo/Orange</material>
  </gazebo>
  <link name="world"/>
  <joint name="fixed1" type="fixed">
    <parent link="world"/>
    <child link="base"/>
    <origin rpy="0 0 0" xyz="0 0 0"/>
  </joint>
  <!-- Base Link -->
  <link name="base">
    <collision>
      <origin rpy="0 0 0" xyz="0 0 0.15"/>
      <geometry>
        <cylinder length="0.3" radius="0.2"/>
      </geometry>
    </collision>
    <visual>
      <origin rpy="0 0 0" xyz="0 0 0.15"/>
      <geometry>
        <cylinder length="0.3" radius="0.2"/>
      </geometry>
    </visual>
    <inertial>
      <origin rpy="0 0 0" xyz="0 0 0.15"/>
      <mass value="10"/>
      <inertia ixx="0.31" ixy="0.0" ixz="0.0" iyy="0.31" iyz="0.0" izz="0.2"/>
    </inertial>
  </link>
  <joint name="joint1" type="continuous">
    <parent link="base"/>
    <child link="link1"/>
    <origin rpy="0 0 0" xyz="0 0 0.3"/>
    <axis xyz="0 0 1"/>
    <dynamics damping="0.7"/>
    <limit effort="1000" velocity="2"/>
  </joint>
  <link name="link1">
    <collision>
      <origin rpy="0 0 0" xyz="0 0 0.5"/>
      <geometry>
        <box size="0.1 0.1 1"/>
      </geometry>
    </collision>
    <visual>
      <origin rpy="0 0 0" xyz="0 0 0.5"/>
      <geometry>
        <box size="0.1 0.1 1"/>
      </geometry>
    </visual>
    <inertial>
      <origin rpy="0 0 0" xyz="0 0 0.5"/>
      <mass value="1"/>
      <inertia ixx="0.08416666666666667" ixy="0.0" ixz="0.0" iyy="0.001666666666666667" iyz="0.0" izz="0.08416666666666667"/>
    </inertial>
  </link>
  <joint name="fixed2" type="fixed">
    <parent link="link1"/>
    <child link="link1_h"/>
    <origin rpy="0 0 0" xyz="0 0 1"/>
    <!-- <axis xyz="0 0 1"/> -->
    <!-- <dynamics damping="0.7"/> -->
  </joint>
  <link name="link1_h">
    <collision>
      <origin rpy="1.57 0 0" xyz="0 0.5 0"/>
      <geometry>
        <box size="0.1 0.1 1"/>
      </geometry>
    </collision>
    <visual>
      <origin rpy="1.57 0 0" xyz="0 0.5 0"/>
      <geometry>
        <box size="0.1 0.1 1"/>
      </geometry>
    </visual>
    <inertial>
      <origin rpy="1.57 0 0" xyz="0 0.5 0"/>
      <mass value="1"/>
      <inertia ixx="0.08416666666666667" ixy="0.0" ixz="0.0" iyy="0.001666666666666667" iyz="0.0" izz="0.08416666666666667"/>
    </inertial>
  </link>
  <joint name="cyl_joint1" type="fixed">
    <parent link="link1_h"/>
    <child link="cyl1"/>
    <origin rpy="0 0 0" xyz="0 1 0"/>
  </joint>
  <!-- Base Link -->
  <link name="cyl1">
    <collision>
      <origin rpy="0 0 0" xyz="0 0 0"/>
      <geometry>
        <cylinder length="0.12" radius="0.1"/>
      </geometry>
    </collision>
    <visual>
      <origin rpy="0 0 0" xyz="0 0 0"/>
      <geometry>
        <cylinder length="0.12" radius="0.1"/>
      </geometry>
    </visual>
    <inertial>
      <origin rpy="0 0 0" xyz="0 0 0"/>
      <mass value="2"/>
      <inertia ixx="0.31" ixy="0.0" ixz="0.0" iyy="0.31" iyz="0.0" izz="0.2"/>
    </inertial>
  </link>
  <joint name="joint2" type="continuous">
    <parent link="cyl1"/>
    <child link="link2"/>
    <origin rpy="0 0 0" xyz="0 0 0"/>
    <axis xyz="0 0 1"/>
    <dynamics damping="0.7"/>
    <limit effort="1000" velocity="2"/>
  </joint>
  <link name="link2">
    <collision>
      <origin rpy="1.57 0 0" xyz="0 0.5 0"/>
      <geometry>
        <box size="0.1 0.1 1"/>
      </geometry>
    </collision>
    <visual>
      <origin rpy="1.57 0 0" xyz="0 0.5 0"/>
      <geometry>
        <box size="0.1 0.1 1"/>
      </geometry>
    </visual>
    <inertial>
      <origin rpy="1.57 0 0" xyz="0 0.5 0"/>
      <mass value="1"/>
      <inertia ixx="0.08416666666666667" ixy="0.0" ixz="0.0" iyy="0.001666666666666667" iyz="0.0" izz="0.08416666666666667"/>
    </inertial>
  </link>
  <joint name="cyl_joint2" type="fixed">
    <parent link="link2"/>
    <child link="cyl2"/>
    <origin rpy="0 0 0" xyz="0 1 0"/>
  </joint>
  <link name="cyl2">
    <collision>
      <origin rpy="0 0 0" xyz="0 0 0"/>
      <geometry>
        <cylinder length="0.1" radius="0.1"/>
      </geometry>
    </collision>
    <visual>
      <origin rpy="0 0 0" xyz="0 0 0"/>
      <geometry>
        <cylinder length="0.1" radius="0.1"/>
      </geometry>
    </visual>
    <inertial>
      <origin rpy="0 0 0" xyz="0 0 0"/>
      <mass value="2"/>
      <inertia ixx="0.31" ixy="0.0" ixz="0.0" iyy="0.31" iyz="0.0" izz="0.2"/>
    </inertial>
  </link>
  <joint name="joint3" type="prismatic">
    <parent link="cyl2"/>
    <child link="link3"/>
    <origin rpy="0 0 0" xyz="0 0 0"/>
    <axis xyz="0 0 -1"/>
    <limit effort="1000" lower="0" upper="1" velocity="2"/>
  </joint>
  <link name="link3">
    <collision>
      <origin rpy="0 0 0" xyz="0 0 0.5"/>
      <geometry>
        <cylinder length="1" radius="0.05"/>
      </geometry>
    </collision>
    <visual>
      <origin rpy="0 0 0" xyz="0 0 0.5"/>
      <geometry>
        <cylinder length="1" radius="0.05"/>
      </geometry>
    </visual>
    <inertial>
      <origin rpy="0 0 0" xyz="0 0 0.5"/>
      <mass value="0.1"/>
      <inertia ixx="0.008395833333333333" ixy="0.0" ixz="0.0" iyy="0.008395833333333333" iyz="0.0" izz="0.00012500000000000003"/>
    </inertial>
  </link>
  <transmission name="tran1">
    <type>transmission_interface/SimpleTransmission</type>
    <joint name="joint1">
      <hardwareInterface>hardware_interface/EffortJointInterface</hardwareInterface>
    </joint>
    <actuator name="motor1">
      <hardwareInterface>hardware_interface/EffortJointInterface</hardwareInterface>
      <mechanicalReduction>1</mechanicalReduction>
    </actuator>
  </transmission>
  <transmission name="tran2">
    <type>transmission_interface/SimpleTransmission</type>
    <joint name="joint2">
      <hardwareInterface>hardware_interface/EffortJointInterface</hardwareInterface>
    </joint>
    <actuator name="motor2">
      <hardwareInterface>hardware_interface/EffortJointInterface</hardwareInterface>
      <mechanicalReduction>1</mechanicalReduction>
    </actuator>
  </transmission>
  <transmission name="tran3">
    <type>transmission_interface/SimpleTransmission</type>
    <joint name="joint3">
      <hardwareInterface>hardware_interface/EffortJointInterface</hardwareInterface>
    </joint>
    <actuator name="motor3">
      <hardwareInterface>hardware_interface/EffortJointInterface</hardwareInterface>
      <mechanicalReduction>1</mechanicalReduction>
    </actuator>
  </transmission>
</robot>
